Workbook

Sheet Notice
B1: Simulateur prospectif TCO + ROI — cadre Foyer, ancré sur KoproGo
B3: Ce qu'il fait
B4: Projette, jalon par jalon, le coût total de possession (fabrication + évolution + maintenance + exploitation) et la valeur (revenu d'abonnement + coût évité) d'une application full-stack stateful, piloté par une trajectoire d'adoption. Il révèle le point de croisement (quand la valeur cumulée dépasse le coût) et les marches de scaling de l'infrastructure.
B6: La logique en une phrase
B7: Chaque coût est une boucle de rétroaction regardée en régime permanent : fabrication/évolution = boucles cycle-dev ; maintenance = taux des boucles (dérive, findings, support) ; exploitation = la boucle GitOps qui tourne. Le TCO est l'intégrale des boucles dans le temps, paramétrée par l'adoption.
B9: Code couleur (convention financière)
B10: • Bleu = saisie modifiable (hypothèse que vous changez pour vos scénarios)
B11: • Noir = formule calculée
B12: • Fond jaune = hypothèse-clé à challenger (les plus sensibles)
B14: Mesuré vs supposé (foyer de lucidité)
B15: MESURÉ (KoproGo réel, sourcé) : capacité 2 500 copros/VPS, 287 req/s, storage 0,027 €/copro/mois, prix OVH 2025, et les paliers infra publiés 8/18/29/163 € aux 100/1000/2000/5000 copros — qui servent à VÉRIFIER le modèle (onglet Modele, ligne 'Contrôle').
B16: SUPPOSÉ (à challenger) : la trajectoire d'adoption (scénario neutre), le nombre de stories par jalon, le ratio de supervision (plafond répondre-de), le coût/tour en tokens, et la cadence calendaire des jalons. Tout est en bleu/jaune, donc falsifiable.
... B22: L'infra est solide jusqu'au plafond VPS (le modèle reproduit 8/18/29 € à <1 % près). Au-delà de ~3 000 copros, l'architecture change (K8s multi-région, HA, 3-AZ) : ce palier est calibré sur l'estimation KoproGo (163 € @ 5 000) — un prior à confirmer par tests de charge, pas une mesure. Le runtime exact ne sort que des tests @edge/load.

Sheet Hypotheses
A1: HYPOTHÈSES — valeurs bleues modifiables
A3: MESURÉ — KoproGo réel (sourcé)
A4: Capacité par nœud VPS | B4: 2500 | C4: copros | D4: Doc COST KoproGo : 2000-3000 conservateur (max 6239)
A5: Storage par copro / mois | B5: 0.027 | C5: € | D5: Doc COST : 200Mo/an, tiered SSD+S3, ~0,027€
A6: CO₂ par requête | B6: 0.12 | C6: g | D6: PERFORMANCE_REPORT KoproGo (287 req/s @1vCPU)
A8: PRIX OVH 2025 (validés)
A9: Prix nœud VPS Value / mois | B9: 7.02 | C9: € TTC | D9: OVH Nov 2025, Value 1vCore/2Go/NVMe, TVA 21%
A10: DNS / mois | B10: 0.1 | C10: € | D10: OVH 2025
A11: Surcoût palier K8s multi-région / mois | B11: 40 | C11: € | D11: Calibré sur palier 5000≈163€ (à confirmer)
A12: Seuil bascule HA / K8s | B12: 3000 | C12: copros | D12: plafond VPS conservateur (3000 copros)
A13: Facteur storage 3-AZ au-delà du seuil | B13: 2 | C13: x | D13: Résilience multi-AZ (0,014 vs 0,007 €/Go)
A15: MODÈLE D'USAGE & PRIX
A16: Part copros cloud (consomment l'infra) | B16: 0.4 | C16: % | D16: Doc COST : 40% cloud / 60% self-hosted
A17: Prix abonnement / copro cloud / mois | B17: 5 | C17: € | D17: Modèle ASBL KoproGo, fixe (baisse par vote AG)
A18: Uplift add-ons / copro cloud / mois | B18: 0 | C18: € | D18: AI+2/IoT/Blockchain — neutre par défaut
A20: FABRICATION — agents IA + superviseur
A21: Prix tokens input | B21: 0.85 | C21: €/Mtok | D21: Tarif fourni
A22: Prix tokens output | B22: 2.55 | C22: €/Mtok | D22: Tarif fourni
A23: Tokens input / tour de boucle | B23: 60000 | C23: tok | D23: Prior point 0 (à resserrer par CSI)
A24: Tokens output / tour de boucle | B24: 15000 | C24: tok | D24: Prior point 0
A25: Tours de boucle / story (moyen) | B25: 6 | C25: tours | D25: Prior point 0, resserré story après story
A26: Jours wall-clock / story (mix S/M/L) | B26: 0.7 | C26: j | D26: S=0,5 / M=0,75 / L=1 (mix)
A27: Coût pair junior+senior / jour | B27: 700 | C27: €/j | D27: 1 junior + 1 senior en pair (TJM cumulé)
A28: Ratio de supervision (agents / pair) | B28: 3 | C28: agents | D28: Plafond répondre-de : au-delà, on n'en répond plus
A30: MAINTENANCE
A31: Maintenance code / an (% du cumul fabriqué) | B31: 0.18 | C31: %/an | D31: Heuristique 15-25% ; alt. = taux des boucles
A32: Tickets support / copro cloud / an | B32: 2 | C32: tickets | D32: Boucle adoption/support
A33: Coût / ticket | B33: 15 | C33: € | D33: Fraction de tour + temps superviseur
A35: VALEUR — coût évité (social, manifeste)
A36: Coût évité / copro / an vs proprio | B36: 240 | C36: €/an | D36: Conservateur (cas KoproGo: 2400€/an possible)

Sheet Modele
A1: TRAJECTOIRE PROSPECTIVE — par jalon
A2: Jalon | C2: J0 | D2: J1 | E2: J2 | F2: J3 | G2: J4 | H2: J5
A3: Mois cumulés (cadence) | C3: =Scenarios!C38 -> 0 | D3: =Scenarios!D38 -> 3 | E3: =Scenarios!E38 -> 9 | F3: =Scenarios!F38 -> 24 | G3: =Scenarios!G38 -> 36 | H3: =Scenarios!H38 -> 54
A4: Mois dans la période | C4: =C3 -> 0 | D4: =D3-C3 -> 3 | E4: =E3-D3 -> 6 | F4: =F3-E3 -> 15 | G4: =G3-F3 -> 12 | H4: =H3-G3 -> 18
A5: Copros (adoption — scénario neutre) | C5: =Scenarios!C9 -> 20 | D5: =Scenarios!D9 -> 50 | E5: =Scenarios!E9 -> 200 | F5: =Scenarios!F9 -> 1000 | G5: =Scenarios!G9 -> 3000 | H5: =Scenarios!H9 -> 5000
A6: Capacités nouvelles = stories | C6: =Scenarios!C18 -> 103 | D6: =Scenarios!D18 -> 25 | E6: =Scenarios!E18 -> 29 | F6: =Scenarios!F18 -> 25 | G6: =Scenarios!G18 -> 16 | H6: =Scenarios!H18 -> 8
A7: — EXPLOITATION / INFRA (€/mois) —
A8: Copros cloud | C8: =C5*Hypotheses!$B$16 -> 8 | D8: =D5*Hypotheses!$B$16 -> 20 | E8: =E5*Hypotheses!$B$16 -> 80 | F8: =F5*Hypotheses!$B$16 -> 400 | G8: =G5*Hypotheses!$B$16 -> 1200 | H8: =H5*Hypotheses!$B$16 -> 2000
A9: Nœuds VPS | C9: =CEILING(C8/(Hypotheses!$B$4*CHOOSE(C44,1,'Compute-Stack'!$B$38,'Compute-Stack'!$B$39)),1) -> 1 | D9: =CEILING(D8/(Hypotheses!$B$4*CHOOSE(D44,1,'Compute-Stack'!$B$38,'Compute-Stack'!$B$39)),1) -> 1 | E9: =CEILING(E8/(Hypotheses!$B$4*CHOOSE(E44,1,'Compute-Stack'!$B$38,'Compute-Stack'!$B$39)),1) -> 1 | F9: =CEILING(F8/(Hypotheses!$B$4*CHOOSE(F44,1,'Compute-Stack'!$B$38,'Compute-Stack'!$B$39)),1) -> 1 | G9: =CEILING(G8/(Hypotheses!$B$4*CHOOSE(G44,1,'Compute-Stack'!$B$38,'Compute-Stack'!$B$39)),1) -> 1 | H9: =CEILING(H8/(Hypotheses!$B$4*CHOOSE(H44,1,'Compute-Stack'!$B$38,'Compute-Stack'!$B$39)),1) -> 1
A10: Multiplicateur HA | C10: =CHOOSE(C44,1,'Compute-Stack'!$B$40,'Compute-Stack'!$B$41) -> 1 | D10: =CHOOSE(D44,1,'Compute-Stack'!$B$40,'Compute-Stack'!$B$41) -> 1 | E10: =CHOOSE(E44,1,'Compute-Stack'!$B$40,'Compute-Stack'!$B$41) -> 1 | F10: =CHOOSE(F44,1,'Compute-Stack'!$B$40,'Compute-Stack'!$B$41) -> 1 | G10: =CHOOSE(G44,1,'Compute-Stack'!$B$40,'Compute-Stack'!$B$41) -> 2 | H10: =CHOOSE(H44,1,'Compute-Stack'!$B$40,'Compute-Stack'!$B$41) -> 2
A11: Compute | C11: =C9*C10*Hypotheses!$B$9+Hypotheses!$B$10+CHOOSE(C44,0,'Compute-Stack'!$B$42,'Compute-Stack'!$B$43) -> 7.12 | D11: =D9*D10*Hypotheses!$B$9+Hypotheses!$B$10+CHOOSE(D44,0,'Compute-Stack'!$B$42,'Compute-Stack'!$B$43) -> 7.12 | E11: =E9*E10*Hypotheses!$B$9+Hypotheses!$B$10+CHOOSE(E44,0,'Compute-Stack'!$B$42,'Compute-Stack'!$B$43) -> 7.12 | F11: =F9*F10*Hypotheses!$B$9+Hypotheses!$B$10+CHOOSE(F44,0,'Compute-Stack'!$B$42,'Compute-Stack'!$B$43) -> 7.12 | G11: =G9*G10*Hypotheses!$B$9+Hypotheses!$B$10+CHOOSE(G44,0,'Compute-Stack'!$B$42,'Compute-Stack'!$B$43) -> 55.14 | H11: =H9*H10*Hypotheses!$B$9+Hypotheses!$B$10+CHOOSE(H44,0,'Compute-Stack'!$B$42,'Compute-Stack'!$B$43) -> 55.14
A12: Storage | C12: =C8*Hypotheses!$B$5*CHOOSE(C44,1,1,'Compute-Stack'!$B$44) -> 0.216 | D12: =D8*Hypotheses!$B$5*CHOOSE(D44,1,1,'Compute-Stack'!$B$44) -> 0.54 | E12: =E8*Hypotheses!$B$5*CHOOSE(E44,1,1,'Compute-Stack'!$B$44) -> 2.16 | F12: =F8*Hypotheses!$B$5*CHOOSE(F44,1,1,'Compute-Stack'!$B$44) -> 10.8 | G12: =G8*Hypotheses!$B$5*CHOOSE(G44,1,1,'Compute-Stack'!$B$44) -> 64.8 | H12: =H8*Hypotheses!$B$5*CHOOSE(H44,1,1,'Compute-Stack'!$B$44) -> 108
A13: Infra totale /mois | C13: =C11+C12 -> 7.336 | D13: =D11+D12 -> 7.66 | E13: =E11+E12 -> 9.28 | F13: =F11+F12 -> 17.92 | G13: =G11+G12 -> 119.94 | H13: =H11+H12 -> 163.14
A14: Contrôle : KoproGo publié | C14: ="—" -> — | D14: =8 -> 8 | E14: =13 -> 13 | F14: =18 -> 18 | G14: ="—" -> — | H14: =163 -> 163
A15: — FABRICATION / ÉVOLUTION (€, capex jalon) —
A16: Coût / tour (tokens) | C16: =(Hypotheses!$B$23*Hypotheses!$B$21+Hypotheses!$B$24*Hypotheses!$B$22)/1000000 -> 0.08925 | D16: =(Hypotheses!$B$23*Hypotheses!$B$21+Hypotheses!$B$24*Hypotheses!$B$22)/1000000 -> 0.08925 | E16: =(Hypotheses!$B$23*Hypotheses!$B$21+Hypotheses!$B$24*Hypotheses!$B$22)/1000000 -> 0.08925 | F16: =(Hypotheses!$B$23*Hypotheses!$B$21+Hypotheses!$B$24*Hypotheses!$B$22)/1000000 -> 0.08925 | G16: =(Hypotheses!$B$23*Hypotheses!$B$21+Hypotheses!$B$24*Hypotheses!$B$22)/1000000 -> 0.08925 | H16: =(Hypotheses!$B$23*Hypotheses!$B$21+Hypotheses!$B$24*Hypotheses!$B$22)/1000000 -> 0.08925
A17: Coût tokens | C17: =C6*Hypotheses!$B$25*C16 -> 55.1565 | D17: =D6*Hypotheses!$B$25*D16 -> 13.3875 | E17: =E6*Hypotheses!$B$25*E16 -> 15.5295 | F17: =F6*Hypotheses!$B$25*F16 -> 13.3875 | G17: =G6*Hypotheses!$B$25*G16 -> 8.568 | H17: =H6*Hypotheses!$B$25*H16 -> 4.284
A18: Jours wall-clock (/ parallélisme) | C18: =C6*Hypotheses!$B$26/Hypotheses!$B$28 -> 24.033333 | D18: =D6*Hypotheses!$B$26/Hypotheses!$B$28 -> 5.8333333 | E18: =E6*Hypotheses!$B$26/Hypotheses!$B$28 -> 6.7666667 | F18: =F6*Hypotheses!$B$26/Hypotheses!$B$28 -> 5.8333333 | G18: =G6*Hypotheses!$B$26/Hypotheses!$B$28 -> 3.7333333 | H18: =H6*Hypotheses!$B$26/Hypotheses!$B$28 -> 1.8666667
A19: Coût superviseur | C19: =C18*Hypotheses!$B$27 -> 16823.333 | D19: =D18*Hypotheses!$B$27 -> 4083.3333 | E19: =E18*Hypotheses!$B$27 -> 4736.6667 | F19: =F18*Hypotheses!$B$27 -> 4083.3333 | G19: =G18*Hypotheses!$B$27 -> 2613.3333 | H19: =H18*Hypotheses!$B$27 -> 1306.6667
A20: Fabrication /jalon | C20: =C17+C19 -> 16878.49 | D20: =D17+D19 -> 4096.7208 | E20: =E17+E19 -> 4752.1962 | F20: =F17+F19 -> 4096.7208 | G20: =G17+G19 -> 2621.9013 | H20: =H17+H19 -> 1310.9507
A21: — MAINTENANCE (€/mois, opex) —
A22: Cumul fabriqué | C22: =C20 -> 16878.49 | D22: =C22+D20 -> 20975.211 | E22: =D22+E20 -> 25727.407 | F22: =E22+F20 -> 29824.128 | G22: =F22+G20 -> 32446.029 | H22: =G22+H20 -> 33756.98
A23: Maintenance code | C23: =C22*Hypotheses!$B$31/12 -> 253.17735 | D23: =D22*Hypotheses!$B$31/12 -> 314.62816 | E23: =E22*Hypotheses!$B$31/12 -> 385.9111 | F23: =F22*Hypotheses!$B$31/12 -> 447.36192 | G23: =G22*Hypotheses!$B$31/12 -> 486.69043 | H23: =H22*Hypotheses!$B$31/12 -> 506.35469
A24: Support (charge adoption) | C24: =C8*Hypotheses!$B$32/12*Hypotheses!$B$33 -> 20 | D24: =D8*Hypotheses!$B$32/12*Hypotheses!$B$33 -> 50 | E24: =E8*Hypotheses!$B$32/12*Hypotheses!$B$33 -> 200 | F24: =F8*Hypotheses!$B$32/12*Hypotheses!$B$33 -> 1000 | G24: =G8*Hypotheses!$B$32/12*Hypotheses!$B$33 -> 3000 | H24: =H8*Hypotheses!$B$32/12*Hypotheses!$B$33 -> 5000
A25: Maintenance /mois | C25: =C23+C24 -> 273.17735 | D25: =D23+D24 -> 364.62816 | E25: =E23+E24 -> 585.9111 | F25: =F23+F24 -> 1447.3619 | G25: =G23+G24 -> 3486.6904 | H25: =H23+H24 -> 5506.3547
A26: — REVENU & VALEUR (€/mois) —
A27: Revenu abonnement /mois | C27: =C8*(Hypotheses!$B$17+Hypotheses!$B$18) -> 40 | D27: =D8*(Hypotheses!$B$17+Hypotheses!$B$18) -> 100 | E27: =E8*(Hypotheses!$B$17+Hypotheses!$B$18) -> 400 | F27: =F8*(Hypotheses!$B$17+Hypotheses!$B$18) -> 2000 | G27: =G8*(Hypotheses!$B$17+Hypotheses!$B$18) -> 6000 | H27: =H8*(Hypotheses!$B$17+Hypotheses!$B$18) -> 10000
A28: Opex /mois (infra+maint) | C28: =C13+C25 -> 280.51335 | D28: =D13+D25 -> 372.28816 | E28: =E13+E25 -> 595.1911 | F28: =F13+F25 -> 1465.2819 | G28: =G13+G25 -> 3606.6304 | H28: =H13+H25 -> 5669.4947
A29: Surplus /mois | C29: =C27-C28 -> -240.51335 | D29: =D27-D28 -> -272.28816 | E29: =E27-E28 -> -195.1911 | F29: =F27-F28 -> 534.71808 | G29: =G27-G28 -> 2393.3696 | H29: =H27-H28 -> 4330.5053
A30: Coût évité /mois (social) | C30: =C5*Hypotheses!$B$36/12 -> 400 | D30: =D5*Hypotheses!$B$36/12 -> 1000 | E30: =E5*Hypotheses!$B$36/12 -> 4000 | F30: =F5*Hypotheses!$B$36/12 -> 20000 | G30: =G5*Hypotheses!$B$36/12 -> 60000 | H30: =H5*Hypotheses!$B$36/12 -> 100000
A31: — CUMULS & ROI —
A32: Capex cumulé | C32: =C20 -> 16878.49 | D32: =C32+D20 -> 20975.211 | E32: =D32+E20 -> 25727.407 | F32: =E32+F20 -> 29824.128 | G32: =F32+G20 -> 32446.029 | H32: =G32+H20 -> 33756.98
A33: Opex cumulé | C33: =C28*C4 -> 0 | D33: =C33+D28*D4 -> 1116.8645 | E33: =D33+E28*E4 -> 4688.0111 | F33: =E33+F28*F4 -> 26667.24 | G33: =F33+G28*G4 -> 69946.805 | H33: =G33+H28*H4 -> 171997.71
A34: Revenu cumulé | C34: =C27*C4 -> 0 | D34: =C34+D27*D4 -> 300 | E34: =D34+E27*E4 -> 2700 | F34: =E34+F27*F4 -> 32700 | G34: =F34+G27*G4 -> 104700 | H34: =G34+H27*H4 -> 284700
A35: Coût total cumulé | C35: =C32+C33 -> 16878.49 | D35: =D32+D33 -> 22092.075 | E35: =E32+E33 -> 30415.418 | F35: =F32+F33 -> 56491.367 | G35: =G32+G33 -> 102392.83 | H35: =H32+H33 -> 205754.69
A36: Surplus cumulé (financier) | C36: =C34-C35 -> -16878.49 | D36: =D34-D35 -> -21792.075 | E36: =E34-E35 -> -27715.418 | F36: =F34-F35 -> -23791.367 | G36: =G34-G35 -> 2307.166 | H36: =H34-H35 -> 78945.311
A37: Seuil financier atteint ? | C37: =IF(C36>=0,"OUI","—") -> — | D37: =IF(D36>=0,"OUI","—") -> — | E37: =IF(E36>=0,"OUI","—") -> — | F37: =IF(F36>=0,"OUI","—") -> — | G37: =IF(G36>=0,"OUI","—") -> OUI | H37: =IF(H36>=0,"OUI","—") -> OUI
A38: Valeur sociale cumulée (coût évité) | C38: =C30*C4 -> 0 | D38: =C38+D30*D4 -> 3000 | E38: =D38+E30*E4 -> 27000 | F38: =E38+F30*F4 -> 327000 | G38: =F38+G30*G4 -> 1047000 | H38: =G38+H30*H4 -> 2847000
A39: ROI social cumulé | C39: =IF(C35=0,0,C38/C35) -> 0 | D39: =IF(D35=0,0,D38/D35) -> 0.1357953 | E39: =IF(E35=0,0,E38/E35) -> 0.88770768 | F39: =IF(F35=0,0,F38/F35) -> 5.788495 | G39: =IF(G35=0,0,G38/G35) -> 10.225325 | H39: =IF(H35=0,0,H38/H35) -> 13.836866
A41: — ARCHITECTURE (tier) —
...

Sheet Graphiques

Sheet Scenarios
A1: SCÉNARIOS D'ADOPTION & CALIBRAGE STORIES
A3: Scénario actif (1=Pess / 2=Neutre / 3=Opt) | C3: 2 | D3: =CHOOSE($C$3,"Pessimiste","Neutre (réaliste)","Optimiste") -> Neutre (réaliste)
A5: Trajectoires copros (source: roadmap KoproGo) | C5: J0 | D5: J1 | E5: J2 | F5: J3 | G5: J4 | H5: J5
A6: Pessimiste (solo dev + IA) | C6: 20 | D6: 50 | E6: 100 | F6: 500 | G6: 1000 | H6: 2000 | J6: Roadmap: An1 50, An2 100, An3 500, An5 2000
A7: Neutre / réaliste | C7: 20 | D7: 50 | E7: 200 | F7: 1000 | G7: 3000 | H7: 5000 | J7: Roadmap: T1 50, T3 200, An2 1000, An3 5000
A8: Optimiste (partenaires+contrib) | C8: 20 | D8: 100 | E8: 500 | F8: 2000 | G8: 5000 | H8: 10000 | J8: Roadmap: M3 50, M6 500, An1 2000, An2 10000
A9: → Copros (scénario actif) | C9: =CHOOSE($C$3,C6,C7,C8) -> 20 | D9: =CHOOSE($C$3,D6,D7,D8) -> 50 | E9: =CHOOSE($C$3,E6,E7,E8) -> 200 | F9: =CHOOSE($C$3,F6,F7,F8) -> 1000 | G9: =CHOOSE($C$3,G6,G7,G8) -> 3000 | H9: =CHOOSE($C$3,H6,H7,H8) -> 5000
A11: Calibrage stories (ancré réel KoproGo)
A12: Endpoints API construits | C12: 559 | J12: README KoproGo (système construit)
A13: Entités DDD | C13: 59
A14: Scénarios BDD | C14: 819 | J14: soit 4 tags/story (@happy @negative @edge @security)
A15: Total stories estimé (= BDD / 4 tags) | C15: =ROUND(C14/4,0) -> 205
A17: Répartition par jalon (part, somme=100%) | C17: 0.5 | D17: 0.12 | E17: 0.14 | F17: 0.12 | G17: 0.08 | H17: 0.04 | J17: J0=fondation (59 entités+core) la plus lourde
A18: → Stories par jalon (calibré) | C18: =ROUND($C$15*C17,0) -> 103 | D18: =ROUND($C$15*D17,0) -> 25 | E18: =ROUND($C$15*E17,0) -> 29 | F18: =ROUND($C$15*F17,0) -> 25 | G18: =ROUND($C$15*G17,0) -> 16 | H18: =ROUND($C$15*H17,0) -> 8
A20: ENVELOPPE — Surplus cumulé par scénario (€) | J20: Adoption seule varie ; fabrication & cadence = communes (Modele). Cadence pess. réelle plus lente : minorant prudent.
A21: Pess: infra /mois | C21: =CEILING((C6*Hypotheses!$B$16)/Hypotheses!$B$4,1)*IF(C6>=Hypotheses!$B$12,2,1)*Hypotheses!$B$9+Hypotheses!$B$10+IF(C6>=Hypotheses!$B$12,Hypotheses!$B$11,0)+(C6*Hypotheses!$B$16)*Hypotheses!$B$5*IF(C6>=Hypotheses!$B$12,Hypotheses!$B$13,1) -> 7.336 | D21: =CEILING((D6*Hypotheses!$B$16)/Hypotheses!$B$4,1)*IF(D6>=Hypotheses!$B$12,2,1)*Hypotheses!$B$9+Hypotheses!$B$10+IF(D6>=Hypotheses!$B$12,Hypotheses!$B$11,0)+(D6*Hypotheses!$B$16)*Hypotheses!$B$5*IF(D6>=Hypotheses!$B$12,Hypotheses!$B$13,1) -> 7.66 | E21: =CEILING((E6*Hypotheses!$B$16)/Hypotheses!$B$4,1)*IF(E6>=Hypotheses!$B$12,2,1)*Hypotheses!$B$9+Hypotheses!$B$10+IF(E6>=Hypotheses!$B$12,Hypotheses!$B$11,0)+(E6*Hypotheses!$B$16)*Hypotheses!$B$5*IF(E6>=Hypotheses!$B$12,Hypotheses!$B$13,1) -> 8.2 | F21: =CEILING((F6*Hypotheses!$B$16)/Hypotheses!$B$4,1)*IF(F6>=Hypotheses!$B$12,2,1)*Hypotheses!$B$9+Hypotheses!$B$10+IF(F6>=Hypotheses!$B$12,Hypotheses!$B$11,0)+(F6*Hypotheses!$B$16)*Hypotheses!$B$5*IF(F6>=Hypotheses!$B$12,Hypotheses!$B$13,1) -> 12.52 | G21: =CEILING((G6*Hypotheses!$B$16)/Hypotheses!$B$4,1)*IF(G6>=Hypotheses!$B$12,2,1)*Hypotheses!$B$9+Hypotheses!$B$10+IF(G6>=Hypotheses!$B$12,Hypotheses!$B$11,0)+(G6*Hypotheses!$B$16)*Hypotheses!$B$5*IF(G6>=Hypotheses!$B$12,Hypotheses!$B$13,1) -> 17.92 | H21: =CEILING((H6*Hypotheses!$B$16)/Hypotheses!$B$4,1)*IF(H6>=Hypotheses!$B$12,2,1)*Hypotheses!$B$9+Hypotheses!$B$10+IF(H6>=Hypotheses!$B$12,Hypotheses!$B$11,0)+(H6*Hypotheses!$B$16)*Hypotheses!$B$5*IF(H6>=Hypotheses!$B$12,Hypotheses!$B$13,1) -> 28.72
A22: Pess: revenu /mois | C22: =(C6*Hypotheses!$B$16)*Hypotheses!$B$17 -> 40 | D22: =(D6*Hypotheses!$B$16)*Hypotheses!$B$17 -> 100 | E22: =(E6*Hypotheses!$B$16)*Hypotheses!$B$17 -> 200 | F22: =(F6*Hypotheses!$B$16)*Hypotheses!$B$17 -> 1000 | G22: =(G6*Hypotheses!$B$16)*Hypotheses!$B$17 -> 2000 | H22: =(H6*Hypotheses!$B$16)*Hypotheses!$B$17 -> 4000
A23: Pess: opex /mois | C23: =C21+Modele!C23+(C6*Hypotheses!$B$16)*Hypotheses!$B$32/12*Hypotheses!$B$33 -> 280.51335 | D23: =D21+Modele!D23+(D6*Hypotheses!$B$16)*Hypotheses!$B$32/12*Hypotheses!$B$33 -> 372.28816 | E23: =E21+Modele!E23+(E6*Hypotheses!$B$16)*Hypotheses!$B$32/12*Hypotheses!$B$33 -> 494.1111 | F23: =F21+Modele!F23+(F6*Hypotheses!$B$16)*Hypotheses!$B$32/12*Hypotheses!$B$33 -> 959.88192 | G23: =G21+Modele!G23+(G6*Hypotheses!$B$16)*Hypotheses!$B$32/12*Hypotheses!$B$33 -> 1504.6104 | H23: =H21+Modele!H23+(H6*Hypotheses!$B$16)*Hypotheses!$B$32/12*Hypotheses!$B$33 -> 2535.0747
A24: Pess: surplus cumulé | C24: =(C22-C23)*Scenarios!C40-Modele!C32 -> -16878.49 | D24: =C24+(D22-D23)*Scenarios!D40-(Modele!D32-Modele!C32) -> -24242.669 | E24: =D24+(E22-E23)*Scenarios!E40-(Modele!E32-Modele!D32) -> -32524.198 | F24: =E24+(F22-F23)*Scenarios!F40-(Modele!F32-Modele!E32) -> -36139.502 | G24: =F24+(G22-G23)*Scenarios!G40-(Modele!G32-Modele!F32) -> -26872.054 | H24: =G24+(H22-H23)*Scenarios!H40-(Modele!H32-Modele!G32) -> 6975.2031
A25: Neutre: infra /mois | C25: =CEILING((C7*Hypotheses!$B$16)/Hypotheses!$B$4,1)*IF(C7>=Hypotheses!$B$12,2,1)*Hypotheses!$B$9+Hypotheses!$B$10+IF(C7>=Hypotheses!$B$12,Hypotheses!$B$11,0)+(C7*Hypotheses!$B$16)*Hypotheses!$B$5*IF(C7>=Hypotheses!$B$12,Hypotheses!$B$13,1) -> 7.336 | D25: =CEILING((D7*Hypotheses!$B$16)/Hypotheses!$B$4,1)*IF(D7>=Hypotheses!$B$12,2,1)*Hypotheses!$B$9+Hypotheses!$B$10+IF(D7>=Hypotheses!$B$12,Hypotheses!$B$11,0)+(D7*Hypotheses!$B$16)*Hypotheses!$B$5*IF(D7>=Hypotheses!$B$12,Hypotheses!$B$13,1) -> 7.66 | E25: =CEILING((E7*Hypotheses!$B$16)/Hypotheses!$B$4,1)*IF(E7>=Hypotheses!$B$12,2,1)*Hypotheses!$B$9+Hypotheses!$B$10+IF(E7>=Hypotheses!$B$12,Hypotheses!$B$11,0)+(E7*Hypotheses!$B$16)*Hypotheses!$B$5*IF(E7>=Hypotheses!$B$12,Hypotheses!$B$13,1) -> 9.28 | F25: =CEILING((F7*Hypotheses!$B$16)/Hypotheses!$B$4,1)*IF(F7>=Hypotheses!$B$12,2,1)*Hypotheses!$B$9+Hypotheses!$B$10+IF(F7>=Hypotheses!$B$12,Hypotheses!$B$11,0)+(F7*Hypotheses!$B$16)*Hypotheses!$B$5*IF(F7>=Hypotheses!$B$12,Hypotheses!$B$13,1) -> 17.92 | G25: =CEILING((G7*Hypotheses!$B$16)/Hypotheses!$B$4,1)*IF(G7>=Hypotheses!$B$12,2,1)*Hypotheses!$B$9+Hypotheses!$B$10+IF(G7>=Hypotheses!$B$12,Hypotheses!$B$11,0)+(G7*Hypotheses!$B$16)*Hypotheses!$B$5*IF(G7>=Hypotheses!$B$12,Hypotheses!$B$13,1) -> 118.94 | H25: =CEILING((H7*Hypotheses!$B$16)/Hypotheses!$B$4,1)*IF(H7>=Hypotheses!$B$12,2,1)*Hypotheses!$B$9+Hypotheses!$B$10+IF(H7>=Hypotheses!$B$12,Hypotheses!$B$11,0)+(H7*Hypotheses!$B$16)*Hypotheses!$B$5*IF(H7>=Hypotheses!$B$12,Hypotheses!$B$13,1) -> 162.14
A26: Neutre: revenu /mois | C26: =(C7*Hypotheses!$B$16)*Hypotheses!$B$17 -> 40 | D26: =(D7*Hypotheses!$B$16)*Hypotheses!$B$17 -> 100 | E26: =(E7*Hypotheses!$B$16)*Hypotheses!$B$17 -> 400 | F26: =(F7*Hypotheses!$B$16)*Hypotheses!$B$17 -> 2000 | G26: =(G7*Hypotheses!$B$16)*Hypotheses!$B$17 -> 6000 | H26: =(H7*Hypotheses!$B$16)*Hypotheses!$B$17 -> 10000
A27: Neutre: opex /mois | C27: =C25+Modele!C23+(C7*Hypotheses!$B$16)*Hypotheses!$B$32/12*Hypotheses!$B$33 -> 280.51335 | D27: =D25+Modele!D23+(D7*Hypotheses!$B$16)*Hypotheses!$B$32/12*Hypotheses!$B$33 -> 372.28816 | E27: =E25+Modele!E23+(E7*Hypotheses!$B$16)*Hypotheses!$B$32/12*Hypotheses!$B$33 -> 595.1911 | F27: =F25+Modele!F23+(F7*Hypotheses!$B$16)*Hypotheses!$B$32/12*Hypotheses!$B$33 -> 1465.2819 | G27: =G25+Modele!G23+(G7*Hypotheses!$B$16)*Hypotheses!$B$32/12*Hypotheses!$B$33 -> 3605.6304 | H27: =H25+Modele!H23+(H7*Hypotheses!$B$16)*Hypotheses!$B$32/12*Hypotheses!$B$33 -> 5668.4947
A28: Neutre: surplus cumulé | C28: =(C26-C27)*Scenarios!C41-Modele!C32 -> -16878.49 | D28: =C28+(D26-D27)*Scenarios!D41-(Modele!D32-Modele!C32) -> -21792.075 | E28: =D28+(E26-E27)*Scenarios!E41-(Modele!E32-Modele!D32) -> -27715.418 | F28: =E28+(F26-F27)*Scenarios!F41-(Modele!F32-Modele!E32) -> -23791.367 | G28: =F28+(G26-G27)*Scenarios!G41-(Modele!G32-Modele!F32) -> 2319.166 | H28: =G28+(H26-H27)*Scenarios!H41-(Modele!H32-Modele!G32) -> 78975.311
A29: Opt: infra /mois | C29: =CEILING((C8*Hypotheses!$B$16)/Hypotheses!$B$4,1)*IF(C8>=Hypotheses!$B$12,2,1)*Hypotheses!$B$9+Hypotheses!$B$10+IF(C8>=Hypotheses!$B$12,Hypotheses!$B$11,0)+(C8*Hypotheses!$B$16)*Hypotheses!$B$5*IF(C8>=Hypotheses!$B$12,Hypotheses!$B$13,1) -> 7.336 | D29: =CEILING((D8*Hypotheses!$B$16)/Hypotheses!$B$4,1)*IF(D8>=Hypotheses!$B$12,2,1)*Hypotheses!$B$9+Hypotheses!$B$10+IF(D8>=Hypotheses!$B$12,Hypotheses!$B$11,0)+(D8*Hypotheses!$B$16)*Hypotheses!$B$5*IF(D8>=Hypotheses!$B$12,Hypotheses!$B$13,1) -> 8.2 | E29: =CEILING((E8*Hypotheses!$B$16)/Hypotheses!$B$4,1)*IF(E8>=Hypotheses!$B$12,2,1)*Hypotheses!$B$9+Hypotheses!$B$10+IF(E8>=Hypotheses!$B$12,Hypotheses!$B$11,0)+(E8*Hypotheses!$B$16)*Hypotheses!$B$5*IF(E8>=Hypotheses!$B$12,Hypotheses!$B$13,1) -> 12.52 | F29: =CEILING((F8*Hypotheses!$B$16)/Hypotheses!$B$4,1)*IF(F8>=Hypotheses!$B$12,2,1)*Hypotheses!$B$9+Hypotheses!$B$10+IF(F8>=Hypotheses!$B$12,Hypotheses!$B$11,0)+(F8*Hypotheses!$B$16)*Hypotheses!$B$5*IF(F8>=Hypotheses!$B$12,Hypotheses!$B$13,1) -> 28.72 | G29: =CEILING((G8*Hypotheses!$B$16)/Hypotheses!$B$4,1)*IF(G8>=Hypotheses!$B$12,2,1)*Hypotheses!$B$9+Hypotheses!$B$10+IF(G8>=Hypotheses!$B$12,Hypotheses!$B$11,0)+(G8*Hypotheses!$B$16)*Hypotheses!$B$5*IF(G8>=Hypotheses!$B$12,Hypotheses!$B$13,1) -> 162.14 | H29: =CEILING((H8*Hypotheses!$B$16)/Hypotheses!$B$4,1)*IF(H8>=Hypotheses!$B$12,2,1)*Hypotheses!$B$9+Hypotheses!$B$10+IF(H8>=Hypotheses!$B$12,Hypotheses!$B$11,0)+(H8*Hypotheses!$B$16)*Hypotheses!$B$5*IF(H8>=Hypotheses!$B$12,Hypotheses!$B$13,1) -> 284.18
A30: Opt: revenu /mois | C30: =(C8*Hypotheses!$B$16)*Hypotheses!$B$17 -> 40 | D30: =(D8*Hypotheses!$B$16)*Hypotheses!$B$17 -> 200 | E30: =(E8*Hypotheses!$B$16)*Hypotheses!$B$17 -> 1000 | F30: =(F8*Hypotheses!$B$16)*Hypotheses!$B$17 -> 4000 | G30: =(G8*Hypotheses!$B$16)*Hypotheses!$B$17 -> 10000 | H30: =(H8*Hypotheses!$B$16)*Hypotheses!$B$17 -> 20000
A31: Opt: opex /mois | C31: =C29+Modele!C23+(C8*Hypotheses!$B$16)*Hypotheses!$B$32/12*Hypotheses!$B$33 -> 280.51335 | D31: =D29+Modele!D23+(D8*Hypotheses!$B$16)*Hypotheses!$B$32/12*Hypotheses!$B$33 -> 422.82816 | E31: =E29+Modele!E23+(E8*Hypotheses!$B$16)*Hypotheses!$B$32/12*Hypotheses!$B$33 -> 898.4311 | F31: =F29+Modele!F23+(F8*Hypotheses!$B$16)*Hypotheses!$B$32/12*Hypotheses!$B$33 -> 2476.0819 | G31: =G29+Modele!G23+(G8*Hypotheses!$B$16)*Hypotheses!$B$32/12*Hypotheses!$B$33 -> 5648.8304 | H31: =H29+Modele!H23+(H8*Hypotheses!$B$16)*Hypotheses!$B$32/12*Hypotheses!$B$33 -> 10790.535
A32: Opt: surplus cumulé | C32: =(C30-C31)*Scenarios!C42-Modele!C32 -> -16878.49 | D32: =C32+(D30-D31)*Scenarios!D42-(Modele!D32-Modele!C32) -> -21643.695 | E32: =D32+(E30-E31)*Scenarios!E42-(Modele!E32-Modele!D32) -> -26091.185 | F32: =E32+(F30-F31)*Scenarios!F42-(Modele!F32-Modele!E32) -> -21044.397 | G32: =F32+(G30-G31)*Scenarios!G42-(Modele!G32-Modele!F32) -> 28547.737 | H32: =G32+(H30-H31)*Scenarios!H42-(Modele!H32-Modele!G32) -> 137750.37
A34: CADENCE CALENDAIRE — mois cumulés par scénario | J34: Durées roadmap KoproGo : pess 4-6 mois/jalon ; opt semaines/jalon
A35: Pessimiste (mois cumulés) | C35: 0 | D35: 12 | E35: 24 | F35: 36 | G35: 60 | H35: 84
A36: Neutre (mois cumulés) | C36: 0 | D36: 3 | E36: 9 | F36: 24 | G36: 36 | H36: 54
A37: Optimiste (mois cumulés) | C37: 0 | D37: 3 | E37: 6 | F37: 12 | G37: 24 | H37: 36
A38: → Mois cumulés (scénario actif) | C38: =CHOOSE($C$3,C35,C36,C37) -> 0 | D38: =CHOOSE($C$3,D35,D36,D37) -> 3 | E38: =CHOOSE($C$3,E35,E36,E37) -> 9 | F38: =CHOOSE($C$3,F35,F36,F37) -> 24 | G38: =CHOOSE($C$3,G35,G36,G37) -> 36 | H38: =CHOOSE($C$3,H35,H36,H37) -> 54
A40: Pess Δmois | C40: =C35 -> 0 | D40: =D35-C35 -> 12 | E40: =E35-D35 -> 12 | F40: =F35-E35 -> 12 | G40: =G35-F35 -> 24 | H40: =H35-G35 -> 24
A41: Neutre Δmois | C41: =C36 -> 0 | D41: =D36-C36 -> 3 | E41: =E36-D36 -> 6 | F41: =F36-E36 -> 15 | G41: =G36-F36 -> 12 | H41: =H36-G36 -> 18
A42: Opt Δmois | C42: =C37 -> 0 | D42: =D37-C37 -> 3 | E42: =E37-D37 -> 3 | F42: =F37-E37 -> 6 | G42: =G37-F37 -> 12 | H42: =H37-G37 -> 12

Sheet Sensibilite
A1: ANALYSE DE SENSIBILITÉ (tornado) — surplus cumulé J5
A2: Instantané scénario neutre. Base = 78 975 €. Variation ±25% par entrée autres figées.
A4: Entrée (±25%) | B4: Base | C4: Surplus si bas | D4: Surplus si haut | E4: Amplitude
A5: Tokens output/tour | B5: 15000 | C5: 78996 | D5: 78955 | E5: 41
A6: Tokens input/tour | B6: 60000 | C6: 79003 | D6: 78948 | E6: 55
A7: Tours / story | B7: 6 | C7: 79023 | D7: 78927 | E7: 96
A8: Surcoût K8s | B8: 40 | C8: 79275 | D8: 78675 | E8: 600
A9: Maintenance %/an | B9: 0.18 | C9: 85206 | D9: 72744 | E9: 12462
A10: Coût pair / jour | B10: 700 | C10: 93598 | D10: 64353 | E10: 29245
A11: Jours / story | B11: 0.7 | C11: 93598 | D11: 64353 | E11: 29245
A12: Ratio supervision | B12: 3 | C12: 59479 | D12: 90673 | E12: 31194
A13: Tickets / copro/an | B13: 2 | C13: 114563 | D13: 43388 | E13: 71175
A15: Ligne de base (surplus J5) | B15: 78975
A16: VOLET SOCIAL — tornado sur le ROI social cumulé J5
A17: Base ROI social = 1384%. Le coût évité (exclu du surplus financier) domine ici — miroir du volet financier.
A18: Entrée (±25%) | B18: ROI social si bas | C18: ROI social si haut | D18: Amplitude (pts)
A19: Tours / story | B19: 13.8421 | C19: 13.8357 | D19: 0.0064
A20: Surcoût K8s | B20: 13.8591 | C20: 13.8187 | D20: 0.0404
A21: Maintenance %/an | B21: 14.2711 | C21: 13.432 | D21: 0.8391
A22: Coût pair / jour | B22: 14.8978 | C22: 12.9205 | D22: 1.9773
A23: Jours / story | B23: 14.8978 | C23: 12.9205 | D23: 1.9773
A24: Ratio supervision | B24: 12.6409 | C24: 14.6732 | D24: 2.0323
A25: Tickets / copro/an | B25: 16.7336 | C25: 11.798 | D25: 4.9356
A26: Coût évité / copro | B26: 10.3792 | C26: 17.2986 | D26: 6.9194

Sheet Financement
A1: TRAME DE FINANCEMENT — creux de trésorerie à tenir
A2: Le besoin de financement = le point le plus bas du surplus cumulé : le capital à sécuriser pour survivre jusqu'au croisement.
A4: Scénario | B4: Besoin financement max | C4: Jalon du creux | D4: Mois du creux | E4: Jalon de croisement | F4: Mois croisement
A5: Pessimiste | B5: =-MIN(Scenarios!$C$24:$H$24) -> 36139.502 | C5: =INDEX(Scenarios!$C$5:$H$5,MATCH(MIN(Scenarios!$C$24:$H$24),Scenarios!$C$24:$H$24,0)) -> J3 | D5: =INDEX(Scenarios!$C$35:$H$35,MATCH(MIN(Scenarios!$C$24:$H$24),Scenarios!$C$24:$H$24,0)) -> 36 | E5: =IF(COUNTIF(Scenarios!$C$24:$H$24,"<0")>=6,"non atteint",INDEX(Scenarios!$C$5:$H$5,COUNTIF(Scenarios!$C$24:$H$24,"<0")+1)) -> J5 | F5: =IF(COUNTIF(Scenarios!$C$24:$H$24,"<0")>=6,"—",INDEX(Scenarios!$C$35:$H$35,COUNTIF(Scenarios!$C$24:$H$24,"<0")+1)) -> 84
A6: Neutre | B6: =-MIN(Scenarios!$C$28:$H$28) -> 27715.418 | C6: =INDEX(Scenarios!$C$5:$H$5,MATCH(MIN(Scenarios!$C$28:$H$28),Scenarios!$C$28:$H$28,0)) -> J2 | D6: =INDEX(Scenarios!$C$36:$H$36,MATCH(MIN(Scenarios!$C$28:$H$28),Scenarios!$C$28:$H$28,0)) -> 9 | E6: =IF(COUNTIF(Scenarios!$C$28:$H$28,"<0")>=6,"non atteint",INDEX(Scenarios!$C$5:$H$5,COUNTIF(Scenarios!$C$28:$H$28,"<0")+1)) -> J4 | F6: =IF(COUNTIF(Scenarios!$C$28:$H$28,"<0")>=6,"—",INDEX(Scenarios!$C$36:$H$36,COUNTIF(Scenarios!$C$28:$H$28,"<0")+1)) -> 36
A7: Optimiste | B7: =-MIN(Scenarios!$C$32:$H$32) -> 26091.185 | C7: =INDEX(Scenarios!$C$5:$H$5,MATCH(MIN(Scenarios!$C$32:$H$32),Scenarios!$C$32:$H$32,0)) -> J2 | D7: =INDEX(Scenarios!$C$37:$H$37,MATCH(MIN(Scenarios!$C$32:$H$32),Scenarios!$C$32:$H$32,0)) -> 6 | E7: =IF(COUNTIF(Scenarios!$C$32:$H$32,"<0")>=6,"non atteint",INDEX(Scenarios!$C$5:$H$5,COUNTIF(Scenarios!$C$32:$H$32,"<0")+1)) -> J4 | F7: =IF(COUNTIF(Scenarios!$C$32:$H$32,"<0")>=6,"—",INDEX(Scenarios!$C$37:$H$37,COUNTIF(Scenarios!$C$32:$H$32,"<0")+1)) -> 24
A9: Lecture : un creux profond et durable (pessimiste) = risque de survie, même si le projet finit par croiser. C'est la trésorerie, pas le ROI, qui tue un projet.

Sheet Schema-Empreinte
A1: SCHÉMA DB & EMPREINTE MÉMOIRE — prospectif par jalon
A2: Le working set PostgreSQL (lignes chaudes + index) doit tenir en RAM pour garder 287 req/s P99<1s. Le schéma grossit avec la roadmap ; l'accumulatif grossit avec le temps.
A4: Jalon | C4: J0 | D4: J1 | E4: J2 | F4: J3 | G4: J4 | H4: J5
A5: Copros cloud (← Modele) | C5: =Modele!C8 -> 8 | D5: =Modele!D8 -> 20 | E5: =Modele!E8 -> 80 | F5: =Modele!F8 -> 400 | G5: =Modele!G8 -> 1200 | H5: =Modele!H8 -> 2000 | J5: Suit le scénario actif
A6: Mois écoulés (← Modele) | C6: =Modele!C3 -> 0 | D6: =Modele!D3 -> 3 | E6: =Modele!E3 -> 9 | F6: =Modele!F3 -> 24 | G6: =Modele!G3 -> 36 | H6: =Modele!H3 -> 54
A7: — SCHÉMA (entités cumulées) —
A8: Entités DDD cumulées | C8: 59 | D8: 63 | E8: 75 | F8: 85 | G8: 91 | H8: 100 | J8: J0=59 réel ; deltas roadmap (GDPR/compta/communauté/IA-IoT)
A9: — PARAMÈTRES DONNÉES (modifiables) —
A10: Lignes statiques / entité / copro | C10: 12 | J10: CRUD: units, owners, comptes PCMN... (moyenne)
A11: Lignes accumulées / copro / mois | C11: 90 | J11: Audit, transactions, votes, doc-méta (croît dans le temps)
A12: Taille moyenne ligne (Ko) | C12: 0.4
A13: Facteur index (x données) | C13: 1.6 | J13: Index doivent rester chauds
A14: Fraction données chaudes (working set) | C14: 0.3
A15: RAM utile DB / nœud (Go) | C15: ='Compute-Stack'!B22 -> 1.4060659 | J15: VPS 2Go − OS/app
A16: — EMPREINTE PAR COPRO —
A17: Lignes / copro | C17: =C8*$C$10+$C$11*C6 -> 708 | D17: =D8*$C$10+$C$11*D6 -> 1026 | E17: =E8*$C$10+$C$11*E6 -> 1710 | F17: =F8*$C$10+$C$11*F6 -> 3180 | G17: =G8*$C$10+$C$11*G6 -> 4332 | H17: =H8*$C$10+$C$11*H6 -> 6060
A18: Données / copro (Mo) | C18: =C17*$C$12/1024 -> 0.2765625 | D18: =D17*$C$12/1024 -> 0.40078125 | E18: =E17*$C$12/1024 -> 0.66796875 | F18: =F17*$C$12/1024 -> 1.2421875 | G18: =G17*$C$12/1024 -> 1.6921875 | H18: =H17*$C$12/1024 -> 2.3671875
A19: Index / copro (Mo) | C19: =C18*($C$13-1) -> 0.1659375 | D19: =D18*($C$13-1) -> 0.24046875 | E19: =E18*($C$13-1) -> 0.40078125 | F19: =F18*($C$13-1) -> 0.7453125 | G19: =G18*($C$13-1) -> 1.0153125 | H19: =H18*($C$13-1) -> 1.4203125
A20: — EMPREINTE TOTALE & RAM —
A21: DB totale (Go) | C21: =(C18+C19)*C5/1024 -> 0.0034570313 | D21: =(D18+D19)*D5/1024 -> 0.012524414 | E21: =(E18+E19)*E5/1024 -> 0.083496094 | F21: =(F18+F19)*F5/1024 -> 0.77636719 | G21: =(G18+G19)*G5/1024 -> 3.1728516 | H21: =(H18+H19)*H5/1024 -> 7.3974609
A22: Working set requis (Go) | C22: =(C19+$C$14*C18)*C5/1024 -> 0.0019445801 | D22: =(D19+$C$14*D18)*D5/1024 -> 0.0070449829 | E22: =(E19+$C$14*E18)*E5/1024 -> 0.046966553 | F22: =(F19+$C$14*F18)*F5/1024 -> 0.43670654 | G22: =(G19+$C$14*G18)*G5/1024 -> 1.784729 | H22: =(H19+$C$14*H18)*H5/1024 -> 4.1610718 | J22: Index (chauds) + fraction chaude des données
A23: RAM disponible (nœuds × utile) (Go) | C23: =Modele!C9*$C$15 -> 1.4060659 | D23: =Modele!D9*$C$15 -> 1.4060659 | E23: =Modele!E9*$C$15 -> 1.4060659 | F23: =Modele!F9*$C$15 -> 1.4060659 | G23: =Modele!G9*$C$15 -> 1.4060659 | H23: =Modele!H9*$C$15 -> 1.4060659
A24: Pression RAM (working set / dispo) | C24: =C22/C23 -> 0.0013829935 | D24: =D22/D23 -> 0.0050104214 | E24: =E22/E23 -> 0.033402809 | F24: =F22/F23 -> 0.31058753 | G24: =G22/G23 -> 1.2693068 | H24: =H22/H23 -> 2.9593717
A25: Mur mémoire ? | C25: =IF(C24>=1,"⛔ SATURÉ",IF(C24>=0.8,"⚠ proche","✓ ok")) -> ✓ ok | D25: =IF(D24>=1,"⛔ SATURÉ",IF(D24>=0.8,"⚠ proche","✓ ok")) -> ✓ ok | E25: =IF(E24>=1,"⛔ SATURÉ",IF(E24>=0.8,"⚠ proche","✓ ok")) -> ✓ ok | F25: =IF(F24>=1,"⛔ SATURÉ",IF(F24>=0.8,"⚠ proche","✓ ok")) -> ✓ ok | G25: =IF(G24>=1,"⛔ SATURÉ",IF(G24>=0.8,"⚠ proche","✓ ok")) -> ⛔ SATURÉ | H25: =IF(H24>=1,"⛔ SATURÉ",IF(H24>=0.8,"⚠ proche","✓ ok")) -> ⛔ SATURÉ
A27: ════ INTERRUPTEUR IoT (série temporelle) ════
A28: IoT activé ? (1=oui / 0=non) | C28: 1 | J28: Bascule pour comparer avec/sans IoT
A29: Adoption add-on IoT / jalon | C29: 0 | D29: 0 | E29: 0 | F29: 0.05 | G29: 0.15 | H29: 0.3 | J29: PropTech 2.0 : tardif et partiel (opt-in payant)
A30: Capteurs / copro | C30: 5 | J30: eau, élec, gaz, température, humidité
A31: Relevés / capteur / heure | C31: 4 | J31: 4 = un relevé / 15 min
A32: Taille ligne relevé (Ko) | C32: 0.05
A33: Rétention brute (mois) | C33: 12 | J33: Fenêtre conservée chaude/tiède
A34: Fraction chaude série temporelle | C34: 0.05 | J34: TS surtout froide ; récent chaud
A35: — EMPREINTE IoT —
A36: Lignes IoT / copro (fenêtre) | C36: =$C$30*$C$31*730*$C$33 -> 175200 | D36: =$C$30*$C$31*730*$C$33 -> 175200 | E36: =$C$30*$C$31*730*$C$33 -> 175200 | F36: =$C$30*$C$31*730*$C$33 -> 175200 | G36: =$C$30*$C$31*730*$C$33 -> 175200 | H36: =$C$30*$C$31*730*$C$33 -> 175200 | J36: capteurs × freq × 730h × rétention
A37: Copros IoT | C37: =C5*C29*$C$28 -> 0 | D37: =D5*D29*$C$28 -> 0 | E37: =E5*E29*$C$28 -> 0 | F37: =F5*F29*$C$28 -> 20 | G37: =G5*G29*$C$28 -> 180 | H37: =H5*H29*$C$28 -> 600
A38: Volume IoT total (Go) | C38: =C36*$C$32/1024*C37/1024 -> 0 | D38: =D36*$C$32/1024*D37/1024 -> 0 | E38: =E36*$C$32/1024*E37/1024 -> 0 | F38: =F36*$C$32/1024*F37/1024 -> 0.16708374 | G38: =G36*$C$32/1024*G37/1024 -> 1.5037537 | H38: =H36*$C$32/1024*H37/1024 -> 5.0125122
A39: Working set IoT (Go) | C39: =($C$34+($C$13-1))*C38 -> 0 | D39: =($C$34+($C$13-1))*D38 -> 0 | E39: =($C$34+($C$13-1))*E38 -> 0 | F39: =($C$34+($C$13-1))*F38 -> 0.10860443 | G39: =($C$34+($C$13-1))*G38 -> 0.97743988 | H39: =($C$34+($C$13-1))*H38 -> 3.2581329 | J39: fraction chaude + index TS
A40: — COMBINÉ (CRUD + IoT) —
A41: Working set TOTAL (Go) | C41: =C22+C39 -> 0.0019445801 | D41: =D22+D39 -> 0.0070449829 | E41: =E22+E39 -> 0.046966553 | F41: =F22+F39 -> 0.54531097 | G41: =G22+G39 -> 2.7621689 | H41: =H22+H39 -> 7.4192047 | J41: base (ligne 22) + IoT
A42: Pression RAM combinée | C42: =C41/C23 -> 0.0013829935 | D42: =D41/D23 -> 0.0050104214 | E42: =E41/E23 -> 0.033402809 | F42: =F41/F23 -> 0.38782745 | G42: =G41/G23 -> 1.9644661 | H42: =H41/H23 -> 5.2765695
...

Sheet Compute-Stack
A1: STACK DE COMPUTE — décomposition mémoire & tiers de déploiement
A2: La RAM utile PostgreSQL = RAM nœud − (OS + orchestration + Traefik + Rust + MinIO + marge + microservices). Le tier et les choix d'archi la rabotent → ils avancent le mur mémoire.
A4: TIER DE DÉPLOIEMENT
A5: Tier (1=Compose / 2=K3s / 3=K8s managé) | B5: 1 | D5: =CHOOSE(B5,"Compose","K3s","K8s managé") -> Compose
A6: EMPREINTE COMPOSANTS PAR NŒUD (Mo)
A7: RAM nœud (VPS) | B7: 2048 | C7: Mo | D7: OVH Value 2Go (mesuré KoproGo)
A8: OS + démon Docker | B8: 300 | C8: Mo | D8: Ubuntu minimal + dockerd
A9: Orchestration (selon tier) | B9: =CHOOSE(B5,0,700,400) -> 0 | C9: Mo | D9: Compose 0 / K3s ~700 / K8s-worker ~400
A10: Traefik (proxy) | B10: =IF(B5=2,0,70) -> 70 | C10: Mo | D10: K3s embarque l'ingress dans l'orchestration
A11: Rust/Actix — base | B11: 130 | C11: Mo | D11: RSS mesuré KoproGo ~128 Mo max
A12: Endpoints API | B12: 559 | D12: README KoproGo
A13: RSS / endpoint | B13: 15 | C13: Ko | D13: Croissance text-segment (modeste en RAM)
A14: Rust — part endpoints | B14: =B12*B13/1024 -> 8.1884766 | C14: Mo | D14: endpoints × Ko/endpoint
A15: MinIO auto-hébergé ? (1/0) | B15: 0 | D15: Prod KoproGo = S3 OVH managé → 0
A16: MinIO | B16: =B15*200 -> 0 | C16: Mo
A17: Microservices co-localisés (nb) | B17: 0 | D17: Bounded contexts extraits sur ce nœud
A18: Overhead / microservice | B18: 100 | C18: Mo | D18: Runtime Rust idle + pool
A19: Microservices | B19: =B17*B18 -> 0 | C19: Mo
A20: Marge sécurité | B20: 100 | C20: Mo
A21: → RAM dispo PostgreSQL | B21: =B7-(B8+B9+B10+B11+B14+B16+B19+B20) -> 1439.8115 | C21: Mo | D21: nœud − (OS + reste)
A22: → RAM dispo PostgreSQL (Go) | B22: =B21/1024 -> 1.4060659 | C22: Go | D22: ← injecté dans Schema-Empreinte
A23: BINAIRE / IMAGE RUST (croissance endpoints)
A24: Image base (distroless+rust) | B24: 80 | C24: Mo
A25: Ko / endpoint (binaire) | B25: 20 | C25: Ko | D25: Code généré par endpoint
A26: Taille image | B26: =B24+B12*B25/1024 -> 90.917969 | C26: Mo | D26: → déploiement, registre, cold-start
A27: Note : les endpoints gonflent surtout l'IMAGE (disque, registre, cold-start) ; l'impact RAM résident reste modeste (Rust mappe le text-segment).
A28: EXTRACTION DDD — relief du mur mémoire
A29: Contexte IoT extrait vers TSDB ? (1/0) | B29: 0 | D29: Sort la série temporelle de PostgreSQL
A30: WS PostgreSQL @ J5 — IoT dans PG | B30: ='Schema-Empreinte'!H41 -> 7.4192047
A31: WS PostgreSQL @ J5 — IoT en TSDB (CRUD seul) | B31: ='Schema-Empreinte'!H22 -> 4.1610718
A32: → WS effectif @ J5 (selon extraction) | B32: =IF(B29=1,B31,B30) -> 7.4192047
A34: Lecture : extraire le bounded context IoT vers un TSDB dédié (DDD le permet proprement) retire la série temporelle du working set PostgreSQL — c'est LE levier qui recule le mur. Choix irréversible (migration de données) → ADR.
A37: COÛT PAR TIER (calibré sur paliers KoproGo)
A38: K3s — facteur capacité/nœud | B38: 0.55 | C38: x | D38: Control-plane ampute la RAM PG (0,79/1,41 Go)
A39: K8s — facteur capacité/nœud | B39: 1 | C39: x | D39: Nœuds managés dimensionnés
A40: K3s — multiplicateur HA (nœuds) | B40: 2 | C40: x | D40: Multi-nœud pour redondance
A41: K8s — multiplicateur HA (nœuds) | B41: 2 | C41: x | D41: HA multi-AZ
A42: K3s — forfait /mois | B42: 0 | C42: € | D42: Auto-géré (pas de control-plane payant)
A43: K8s — forfait /mois (LB+managé) | B43: 41 | C43: € | D43: Calibré : palier 5000 ≈ 163€
A44: K8s — facteur storage 3-AZ | B44: 2 | C44: x | D44: Résilience multi-AZ (0,014 vs 0,007 €/Go)
